I'm sorry, but an uncaught exception occurred.

While running game code:
  File "game/script.rpy", line 73, in script call
    call data_dialog_00001_00003
  File "game/dialog/s_00001/a_00003.rpy", line 186, in script
    data_chr_00006_00000 "<we are currently in emergency so i think its fine>"
Exception: Sayer 'data_chr_00006_00000' is not defined.

-- Full Traceback ------------------------------------------------------------

Full traceback:
  File "game/script.rpy", line 73, in script call
    call data_dialog_00001_00003
  File "game/dialog/s_00001/a_00003.rpy", line 186, in script
    data_chr_00006_00000 "<we are currently in emergency so i think its fine>"
  File "C:\Users\a9292\Documents\renpy-8.1.3-sdk\renpy\ast.py", line 890, in execute
    who = eval_who(self.who, self.who_fast)
  File "C:\Users\a9292\Documents\renpy-8.1.3-sdk\renpy\ast.py", line 783, in eval_who
    raise Exception("Sayer '%s' is not defined." % who)
Exception: Sayer 'data_chr_00006_00000' is not defined.

Windows-10-10.0.19041 AMD64
Ren'Py 8.1.3.23091805
Skythread 1.0
Mon Oct 16 14:02:33 2023
